2025-04-18 15:50:05,568 ERROR: Exception on / [GET] [in /mnt/c/Users/DELL/Desktop/blog/my_blog_site_on_flask/venv/lib/python3.11/site-packages/flask/app.py:875]
Traceback (most recent call last):
  File "/mnt/c/Users/DELL/Desktop/blog/my_blog_site_on_flask/venv/lib/python3.11/site-packages/sqlalchemy/engine/base.py", line 1964, in _exec_single_context
    self.dialect.do_execute(
  File "/mnt/c/Users/DELL/Desktop/blog/my_blog_site_on_flask/venv/lib/python3.11/site-packages/sqlalchemy/engine/default.py", line 945, in do_execute
    cursor.execute(statement, parameters)
sqlite3.OperationalError: no such table: user

The above exception was the direct cause of the following exception:

Traceback (most recent call last):
  File "/mnt/c/Users/DELL/Desktop/blog/my_blog_site_on_flask/venv/lib/python3.11/site-packages/flask/app.py", line 1511, in wsgi_app
    response = self.full_dispatch_request()
               ^^^^^^^^^^^^^^^^^^^^^^^^^^^^
  File "/mnt/c/Users/DELL/Desktop/blog/my_blog_site_on_flask/venv/lib/python3.11/site-packages/flask/app.py", line 919, in full_dispatch_request
    rv = self.handle_user_exception(e)
         ^^^^^^^^^^^^^^^^^^^^^^^^^^^^^
  File "/mnt/c/Users/DELL/Desktop/blog/my_blog_site_on_flask/venv/lib/python3.11/site-packages/flask/app.py", line 915, in full_dispatch_request
    rv = self.preprocess_request()
         ^^^^^^^^^^^^^^^^^^^^^^^^^
  File "/mnt/c/Users/DELL/Desktop/blog/my_blog_site_on_flask/venv/lib/python3.11/site-packages/flask/app.py", line 1291, in preprocess_request
    rv = self.ensure_sync(before_func)()
         ^^^^^^^^^^^^^^^^^^^^^^^^^^^^^^^
  File "/mnt/c/Users/DELL/Desktop/blog/my_blog_site_on_flask/app/routes.py", line 95, in before_request
    if current_user.is_authenticated:
       ^^^^^^^^^^^^^^^^^^^^^^^^^^^^^
  File "/mnt/c/Users/DELL/Desktop/blog/my_blog_site_on_flask/venv/lib/python3.11/site-packages/werkzeug/local.py", line 318, in __get__
    obj = instance._get_current_object()
          ^^^^^^^^^^^^^^^^^^^^^^^^^^^^^^
  File "/mnt/c/Users/DELL/Desktop/blog/my_blog_site_on_flask/venv/lib/python3.11/site-packages/werkzeug/local.py", line 526, in _get_current_object
    return get_name(local())
                    ^^^^^^^
  File "/mnt/c/Users/DELL/Desktop/blog/my_blog_site_on_flask/venv/lib/python3.11/site-packages/flask_login/utils.py", line 25, in <lambda>
    current_user = LocalProxy(lambda: _get_user())
                                      ^^^^^^^^^^^
  File "/mnt/c/Users/DELL/Desktop/blog/my_blog_site_on_flask/venv/lib/python3.11/site-packages/flask_login/utils.py", line 370, in _get_user
    current_app.login_manager._load_user()
  File "/mnt/c/Users/DELL/Desktop/blog/my_blog_site_on_flask/venv/lib/python3.11/site-packages/flask_login/login_manager.py", line 364, in _load_user
    user = self._user_callback(user_id)
           ^^^^^^^^^^^^^^^^^^^^^^^^^^^^
  File "/mnt/c/Users/DELL/Desktop/blog/my_blog_site_on_flask/app/models.py", line 110, in load_user
    return db.session.get(User, int(id))
           ^^^^^^^^^^^^^^^^^^^^^^^^^^^^^
  File "/mnt/c/Users/DELL/Desktop/blog/my_blog_site_on_flask/venv/lib/python3.11/site-packages/sqlalchemy/orm/scoping.py", line 1058, in get
    return self._proxied.get(
           ^^^^^^^^^^^^^^^^^^
  File "/mnt/c/Users/DELL/Desktop/blog/my_blog_site_on_flask/venv/lib/python3.11/site-packages/sqlalchemy/orm/session.py", line 3694, in get
    return self._get_impl(
           ^^^^^^^^^^^^^^^
  File "/mnt/c/Users/DELL/Desktop/blog/my_blog_site_on_flask/venv/lib/python3.11/site-packages/sqlalchemy/orm/session.py", line 3874, in _get_impl
    return db_load_fn(
           ^^^^^^^^^^^
  File "/mnt/c/Users/DELL/Desktop/blog/my_blog_site_on_flask/venv/lib/python3.11/site-packages/sqlalchemy/orm/loading.py", line 694, in load_on_pk_identity
    session.execute(
  File "/mnt/c/Users/DELL/Desktop/blog/my_blog_site_on_flask/venv/lib/python3.11/site-packages/sqlalchemy/orm/session.py", line 2365, in execute
    return self._execute_internal(
           ^^^^^^^^^^^^^^^^^^^^^^^
  File "/mnt/c/Users/DELL/Desktop/blog/my_blog_site_on_flask/venv/lib/python3.11/site-packages/sqlalchemy/orm/session.py", line 2251, in _execute_internal
    result: Result[Any] = compile_state_cls.orm_execute_statement(
                          ^^^^^^^^^^^^^^^^^^^^^^^^^^^^^^^^^^^^^^^^
  File "/mnt/c/Users/DELL/Desktop/blog/my_blog_site_on_flask/venv/lib/python3.11/site-packages/sqlalchemy/orm/context.py", line 306, in orm_execute_statement
    result = conn.execute(
             ^^^^^^^^^^^^^
  File "/mnt/c/Users/DELL/Desktop/blog/my_blog_site_on_flask/venv/lib/python3.11/site-packages/sqlalchemy/engine/base.py", line 1416, in execute
    return meth(
           ^^^^^
  File "/mnt/c/Users/DELL/Desktop/blog/my_blog_site_on_flask/venv/lib/python3.11/site-packages/sqlalchemy/sql/elements.py", line 523, in _execute_on_connection
    return connection._execute_clauseelement(
           ^^^^^^^^^^^^^^^^^^^^^^^^^^^^^^^^^^
  File "/mnt/c/Users/DELL/Desktop/blog/my_blog_site_on_flask/venv/lib/python3.11/site-packages/sqlalchemy/engine/base.py", line 1638, in _execute_clauseelement
    ret = self._execute_context(
          ^^^^^^^^^^^^^^^^^^^^^^
  File "/mnt/c/Users/DELL/Desktop/blog/my_blog_site_on_flask/venv/lib/python3.11/site-packages/sqlalchemy/engine/base.py", line 1843, in _execute_context
    return self._exec_single_context(
           ^^^^^^^^^^^^^^^^^^^^^^^^^^
  File "/mnt/c/Users/DELL/Desktop/blog/my_blog_site_on_flask/venv/lib/python3.11/site-packages/sqlalchemy/engine/base.py", line 1983, in _exec_single_context
    self._handle_dbapi_exception(
  File "/mnt/c/Users/DELL/Desktop/blog/my_blog_site_on_flask/venv/lib/python3.11/site-packages/sqlalchemy/engine/base.py", line 2352, in _handle_dbapi_exception
    raise sqlalchemy_exception.with_traceback(exc_info[2]) from e
  File "/mnt/c/Users/DELL/Desktop/blog/my_blog_site_on_flask/venv/lib/python3.11/site-packages/sqlalchemy/engine/base.py", line 1964, in _exec_single_context
    self.dialect.do_execute(
  File "/mnt/c/Users/DELL/Desktop/blog/my_blog_site_on_flask/venv/lib/python3.11/site-packages/sqlalchemy/engine/default.py", line 945, in do_execute
    cursor.execute(statement, parameters)
sqlalchemy.exc.OperationalError: (sqlite3.OperationalError) no such table: user
[SQL: SELECT user.id AS user_id, user.username AS user_username, user.email AS user_email, user.password_hash AS user_password_hash, user.about_me AS user_about_me, user.last_seen AS user_last_seen 
FROM user 
WHERE user.id = ?]
[parameters: (3,)]
(Background on this error at: https://sqlalche.me/e/20/e3q8)
2025-04-18 15:50:59,174 INFO: Microblog startup [in /mnt/c/Users/DELL/Desktop/blog/my_blog_site_on_flask/app/__init__.py:57]
2025-04-18 15:52:35,794 INFO: Microblog startup [in /mnt/c/Users/DELL/Desktop/blog/my_blog_site_on_flask/app/__init__.py:57]
2025-04-18 15:53:09,753 INFO: Microblog startup [in /mnt/c/Users/DELL/Desktop/blog/my_blog_site_on_flask/app/__init__.py:57]
2025-04-18 15:53:51,989 INFO: Microblog startup [in /mnt/c/Users/DELL/Desktop/blog/my_blog_site_on_flask/app/__init__.py:57]
2025-04-18 15:54:12,605 INFO: Microblog startup [in /mnt/c/Users/DELL/Desktop/blog/my_blog_site_on_flask/app/__init__.py:57]
2025-04-18 15:54:28,859 INFO: Microblog startup [in /mnt/c/Users/DELL/Desktop/blog/my_blog_site_on_flask/app/__init__.py:57]
2025-04-18 15:54:40,454 INFO: Microblog startup [in /mnt/c/Users/DELL/Desktop/blog/my_blog_site_on_flask/app/__init__.py:57]
2025-04-18 17:25:39,448 INFO: Microblog startup [in /mnt/c/Users/DELL/Desktop/blog/my_blog_site_on_flask/app/__init__.py:57]
